Workbook
Name USD: #REF!
Name USD: #REF!

Sheet Synthesis 
A1: E-Tech System Limited
A2: for
A3: Ministry of Health & Wellness
A4: Ref # SurACS-1-6-2026 - Surveillance and Access Control System
A5: 46045
A6: COST SUMMARY
A7: Item No | B7: DESIGNATION | C7: Qty | D7: Unit Price in US Dollar (JMD) | E7: TOTAL COST US Dollar (JMD)
A8: Video Surveillance
A9: 100 | B9: ='VSS BoM'!B4 -> Video Management System Software | C9: 1 | D9: ='VSS BoM'!E9 -> 440915.65 | E9: =D9*C9 -> 440915.65
A10: 200 | B10: ='VSS BoM'!B10 -> Compute and Storage | C10: 1 | D10: ='VSS BoM'!E12 -> 1418442.3 | E10: =D10*C10 -> 1418442.3
A11: 300 | B11: ='VSS BoM'!B13 -> Control Room | C11: 1 | D11: ='VSS BoM'!E16 -> 960606.27 | E11: =D11*C11 -> 960606.27
A12: 400 | B12: ='VSS BoM'!B17 -> Video Security Equipment | C12: 1 | D12: ='VSS BoM'!E21 -> 1785999.1 | E12: =D12*C12 -> 1785999.1
A13: 500 | B13: ='VSS BoM'!B22 -> Network | C13: 1 | D13: ='VSS BoM'!E25 -> 353767.05 | E13: =D13*C13 -> 353767.05
A14: 600 | B14: ='VSS BoM'!B26 -> Network Infrastructure | C14: 1 | D14: ='VSS BoM'!E31 -> 632521.5 | E14: =D14*C14 -> 632521.5
A15: 700 | B15: ='VSS BoM'!B32 -> Professional Services | C15: 1 | D15: ='VSS BoM'!E36 -> 926228.58 | E15: =D15*C15 -> 926228.58
A16: ='VSS BoM'!A37 -> 700.5 | B16: ='VSS BoM'!B37 -> Contingency plan | C16: 0 | D16: ='VSS BoM'!C37 -> 591649.3 | E16: =D16*C16 -> 0
A17: 800 | B17: ='VSS BoM'!B39 -> Importation | C17: 1 | D17: ='VSS BoM'!E42 -> 2161897.7 | E17: =D17*C17 -> 2161897.7
A18: Total Video Surveillance | E18: =SUM(E9:E17) -> 8680378.2
A19: Access Control Systems
A20: 900 | B20: ='EAC BoM'!B4 -> Access Control System Software | C20: 1 | D20: ='EAC BoM'!E7 -> 232069.13 | E20: =C20*D20 -> 232069.13
A21: 1000 | B21: ='EAC BoM'!B8 -> Hardware | C21: 1 | D21: ='EAC BoM'!E23 -> 2954611.3 | E21: =C21*D21 -> 2954611.3
A22: 1100 | B22: ='EAC BoM'!B24 -> Infrastructure | C22: 1 | D22: ='EAC BoM'!E29 -> 435699 | E22: =C22*D22 -> 435699
A23: 1200 | B23: ='EAC BoM'!B30 -> Professional Services | C23: 1 | D23: ='EAC BoM'!E34 -> 743050.47 | E23: =C23*D23 -> 743050.47
A24: ='EAC BoM'!A35 -> 1200.5 | B24: ='EAC BoM'!B35 -> Contingency plan | C24: 0 | D24: ='EAC BoM'!C35 -> 609454.01 | E24: =C24*D24 -> 0
A25: 1300 | B25: ='EAC BoM'!B37 -> Importation | C25: 1 | D25: ='EAC BoM'!E40 -> 1359009.2 | E25: =C25*D25 -> 1359009.2
A26: Total Access Control | E26: =SUM(E20:E25) -> 5724439.2
A28: Grand Total Supply, Install, Configure and Commission Security Solution | E28: =E26+E18 -> 14404817
D29: Tax | E29: =E28*0.15 -> 2160722.6
D30: Grand Total | E30: =SUM(E28:E29) -> 16565540

Sheet VSS
A1: Company Name
A2: Address
A3: City/Town | V3: Code
A4: Phone | V4: Web
A5: Company Detail
A7: Notes
A9: Contact
A10: Office Phone | H10: Mobile
A11: Email
A12: Project
A13: Video Surveillance Assessment
A14: LOCATION | C14: Connectivity | H14: L | I14: Camera Resolution | W14: COMMENTS
C15: Switch | F15: Encoder | H15: L | I15: D1 | J15: PTZ-E | K15: PTZ-I | L15: HD | M15: 2MP-B | N15: 2MP-D | O15: 5MP-B | P15: 5MP-D | Q15: 5MP-DV | R15: 4K-B | S15: 4K-D | T15: 180º | U15: 12-360º | V15: THER
C16: 16 | D16: 8 | E16: 4 | F16: 4 | G16: 8 | W16: Switches are on floor 1 and 4 - To be provided by MOH
A17: Ground Floor
A18: Front of Building | C18: 1 | S18: 2 | W18: Outdoor
A19: Side of Building | Q19: 1 | W19: Outdoor
A20: Parking Lot | S20: 1 | W20: Outdoor
A21: Emergency door | Q21: 1 | W21: Outdoor
A22: Lobby | P22: 1
A23: First Floor
A24: Lobby | D24: 1 | P24: 1
A25: Second Floor
A26: Lobby | D26: 1 | P26: 1
A27: Third Floor
A28: Lobby | D28: 1 | P28: 1
A29: Fourth Floor
A30: Lobby | P30: 1
A31: Fifth Floor
A32: Lobby | P32: 1
A33: Sixth Floor
A34: Lobby | P34: 1
A40: Total | C40: =SUM(C18:C39) -> 1 | D40: =SUM(D18:D39) -> 3 | E40: =SUM(E18:E39) -> 0 | F40: =SUM(F18:F39) -> 0 | G40: =SUM(G18:G39) -> 0 | H40: =SUM(H18:H39) -> 0 | I40: =SUM(I18:I39) -> 0 | J40: =SUM(J18:J39) -> 0 | ... V40: =SUM(V18:V39) -> 0 | W40: =SUM(J40:V40) -> 12

Sheet Workbook VSS
A1: Item | B1: Qty | C1: Cost | D1: Markup | E1: Sell | F1: Total Cost | G1: Total Sell | H1: Total Profit
A2: Software
A3: QVM-A-ADV-CP | B3: 0 | C3: 840 | D3: =C3*0.35 -> 294 | E3: =D3+C3 -> 1134 | F3: =C3*B3 -> 0 | G3: =E3*B3 -> 0 | H3: =D3*B3 -> 0
A4: QVM-A-ADV-CP-SMA-EI | B4: 0 | C4: 151.2 | D4: =C4*0.45 -> 68.04 | E4: =D4+C4 -> 219.24 | F4: =C4*B4 -> 0 | G4: =E4*B4 -> 0 | H4: =D4*B4 -> 0
A5: QVM-A-ADV-1C | B5: =VSS!W40 -> 12 | C5: 129 | D5: =C5*0.45 -> 58.05 | E5: =D5+C5 -> 187.05 | F5: =C5*B5 -> 1548 | G5: =E5*B5 -> 2244.6 | H5: =D5*B5 -> 696.6
A6: QVM-A-ADV-1C-SMA-EI | B6: =B5 -> 12 | C6: 26.46 | D6: =C6*0.45 -> 11.907 | E6: =D6+C6 -> 38.367 | F6: =C6*B6 -> 317.52 | G6: =E6*B6 -> 460.404 | H6: =D6*B6 -> 142.884
E7: Total | F7: =SUM(F3:F6) -> 1865.52 | G7: =SUM(G3:G6) -> 2705.004 | H7: =SUM(H3:H6) -> 839.484
A9: Compute & Storage
A10: G2-A2L20A487 | B10: 1 | C10: 6446 | D10: =C10*0.35 -> 2256.1 | E10: =D10+C10 -> 8702.1 | F10: =C10*B10 -> 6446 | G10: =E10*B10 -> 8702.1 | H10: =D10*B10 -> 2256.1
A11: G2-t2#11W005 | B11: 1 | C11: 1865.4 | D11: =C11*0.35 -> 652.89 | E11: =D11+C11 -> 2518.29 | F11: =C11*B11 -> 1865.4 | G11: =E11*B11 -> 2518.29 | H11: =D11*B11 -> 652.89
A12: Shipping | B12: 1 | C12: 2500 | D12: =C12*0.35 -> 875 | E12: =D12+C12 -> 3375 | F12: =C12*B12 -> 2500 | G12: =E12*B12 -> 3375 | H12: =D12*B12 -> 875
E13: Total | F13: =SUM(F10:F12) -> 10811.4 | G13: =SUM(G10:G12) -> 14595.39 | H13: =SUM(H10:H12) -> 3783.99
E14: Import | F14: =F13*0.22 -> 2378.508 | G14: =F14 -> 2378.508
A16: Cameras
A17: AXIS P3268-LVE | B17: =VSS!S40 -> 3 | C17: 824.25 | D17: =C17*0.3 -> 247.275 | E17: =D17+C17 -> 1071.525 | F17: =C17*B17 -> 2472.75 | G17: =E17*B17 -> 3214.575 | H17: =D17*B17 -> 741.825 | I17: =C17*163 -> 134352.75
A18: AXIS P3267-LV | B18: =VSS!P40 -> 7 | C18: 636.75 | D18: =C18*0.3 -> 191.025 | E18: =D18+C18 -> 827.775 | F18: =C18*B18 -> 4457.25 | G18: =E18*B18 -> 5794.425 | H18: =D18*B18 -> 1337.175 | I18: =C18*163 -> 103790.25
A19: AXIS P3267-LVE | B19: =VSS!Q40 -> 2 | C19: 749.25 | D19: =C19*0.3 -> 224.775 | E19: =D19+C19 -> 974.025 | F19: =C19*B19 -> 1498.5 | G19: =E19*B19 -> 1948.05 | H19: =D19*B19 -> 449.55 | I19: =C19*163 -> 122127.75
A20: C43MD-AU-400G | B20: 1 | C20: 599 | D20: =C20*0.3 -> 179.7 | E20: =D20+C20 -> 778.7 | F20: =C20*B20 -> 599 | G20: =E20*B20 -> 778.7 | H20: =D20*B20 -> 179.7 | I20: =C20*163 -> 97637
A21: Shipping | B21: 1 | C21: 1200 | D21: =C21*0.3 -> 360 | E21: =D21+C21 -> 1560 | F21: =C21*B21 -> 1200 | G21: =E21*B21 -> 1560 | H21: =D21*B21 -> 360 | I21: =C21*163 -> 195600
E22: Total | F22: =SUM(F17:F21) -> 10227.5 | G22: =SUM(G17:G21) -> 13295.75 | H22: =SUM(H17:H21) -> 3068.25
E23: Import | F23: =F22*0.44 -> 4500.1 | G23: =G22*0.44 -> 5850.13
A24: Network
A25: AXIS T8516 PoE+ | B25: =VSS!C40 -> 1 | C25: 591.75 | D25: =C25*0.3 -> 177.525 | E25: =D25+C25 -> 769.275 | F25: =C25*B25 -> 591.75 | G25: =E25*B25 -> 769.275 | H25: =D25*B25 -> 177.525 | I25: =C25*163 -> 96455.25
A26: AXIS T8508 POE+ | B26: =VSS!D40 -> 3 | C26: 359.25 | D26: =C26*0.3 -> 107.775 | E26: =D26+C26 -> 467.025 | F26: =C26*B26 -> 1077.75 | G26: =E26*B26 -> 1401.075 | H26: =D26*B26 -> 323.325 | I26: =C26*163 -> 58557.75
A27: Shipping | B27: 1 | C27: 500 | D27: =C27*0.3 -> 150 | E27: =D27+C27 -> 650 | F27: =C27*B27 -> 500 | G27: =E27*B27 -> 650 | H27: =D27*B27 -> 150 | I27: =C27*163 -> 81500
E28: Total | F28: =SUM(F25:F27) -> 2169.5 | G28: =SUM(G25:G27) -> 2820.35 | H28: =SUM(H25:H27) -> 650.85
E29: Import | F29: =F28*0.44 -> 954.58 | G29: =G28*0.44 -> 1240.954
A31: Network Infrastructure
A32: CBL-tC1000f | B32: 6 | C32: 200 | D32: =C32*0.3 -> 60 | E32: =C32+D32 -> 260 | F32: =C32*B32 -> 1200 | G32: =E32*B32 -> 1560 | H32: =D32*B32 -> 360 | I32: =C32*163 -> 32600
A33: Miscellaneous Material | B33: 1 | C33: 700 | D33: =C33*0.3 -> 210 | E33: =C33+D33 -> 910 | F33: =C33*B33 -> 700 | G33: =E33*B33 -> 910 | H33: =D33*B33 -> 210 | I33: =C33*163 -> 114100
A34: Labor Infra | B34: 1 | C34: 500 | D34: =C34*0.3 -> 150 | E34: =C34+D34 -> 650 | F34: =C34*B34 -> 500 | G34: =E34*B34 -> 650 | H34: =D34*B34 -> 150 | I34: =C34*163 -> 81500
A35: Cable | B35: 13 | C35: 45 | D35: =C35*0.3 -> 13.5 | E35: =C35+D35 -> 58.5 | F35: =C35*B35 -> 585 | G35: =E35*B35 -> 760.5 | H35: =D35*B35 -> 175.5 | I35: =C35*163 -> 7335
F36: =SUM(F32:F35) -> 2985 | G36: =SUM(G32:G35) -> 3880.5 | H36: =SUM(H32:H35) -> 895.5
E37: Import | F37: =F32*0.44 -> 528 | G37: =G32*0.44 -> 686.4
A38: Processional Services
A39: LAB-INST-EQUIP | B39: =B26+B25+B19+B18+B17+B11+B10 -> 18 | C39: 100 | D39: =C39*50% -> 50 | E39: =D39+C39 -> 150 | F39: =C39*B39 -> 1800 | G39: =E39*B39 -> 2700 | H39: =D39*B39 -> 900 | I39: =C39*163 -> 16300
A40: LAB-INST-CONFIG | B40: 12 | C40: 25 | D40: =C40*50% -> 12.5 | E40: =D40+C40 -> 37.5 | F40: =C40*B40 -> 300 | G40: =E40*B40 -> 450 | H40: =D40*B40 -> 150 | I40: =C40*163 -> 4075
A41: PM | B41: 1 | C41: 1688.2559 | D41: =C41*50% -> 844.12797 | E41: =D41+C41 -> 2532.3839 | F41: =C41*B41 -> 1688.2559 | G41: =E41*B41 -> 2532.3839 | H41: =D41*B41 -> 844.12797 | I41: =C41*163 -> 275185.72
A42: Contingency plan | B42: 0 | C42: 3629.7503 | E42: =D42+C42 -> 3629.7503 | F42: =C42*B42 -> 0 | G42: =E42*B42 -> 0 | H42: =D42*B42 -> 0 | I42: =C42*163 -> 591649.3
E43: Total | F43: =SUM(F39:F42) -> 3788.2559 | G43: =SUM(G39:G42) -> 5682.3839 | H43: =SUM(H39:H42) -> 1894.128
...

Sheet VSS BoM
A1: Ministry of Health & Wellness
A2: Ref # SurAc-1-6-2026 - Video Surveillance System
A3: Item No | B3: Products – Description | C3: List | D3: Qty | E3: Extended
A4: 100 | B4: Video Management System Software
A5: 100.1 | B5: HxGN QWVMS Advanced Core Package | C5: ='Workbook VSS'!E3*163 -> 184842 | D5: 0 | E5: =C5*D5 -> 0
A6: 100.2 | B6: 1st Yr. Enterprise SMA for Qognify VMS Advanced Core Package | C6: ='Workbook VSS'!E4*163 -> 35736.12 | D6: 0 | E6: =C6*D6 -> 0
A7: 100.3 | B7: HxGN dC3 Advanced Camera Extension | C7: ='Workbook VSS'!E5*163 -> 30489.15 | D7: ='Workbook VSS'!B5 -> 12 | E7: =C7*D7 -> 365869.8 | F7: 30489.15
A8: 100.4 | B8: 1st Yr. Enterprise SMA for Qognify VMS Advanced Camera Extension | C8: ='Workbook VSS'!E6*163 -> 6253.821 | D8: =D7 -> 12 | E8: =C8*D8 -> 75045.852 | F8: 6253.821
C9: VMS Total | E9: =SUM(E5:E8) -> 440915.65
A10: 200 | B10: Compute and Storage
A11: 200.1 | B11: Rasilient ApplianceStor70v3, 1U/4D Rack-mountable, Intel Xeon E-2334 CPU, 32GB DDR4 3200Mhz ECC RAM, 2x GbE, Redundant PSU, On-board ASPEED GPU, 2x240GB SSD, 4x20TB SAS HDD, Win Server 2019 Standard, USB Keyboard and Mouse, 5 Year Warranty | C11: ='Workbook VSS'!E10*163 -> 1418442.3 | D11: ='Workbook VSS'!B10 -> 1 | E11: =C11*D11 -> 1418442.3 | F11: 1418442.3
C12: Server Total | E12: =SUM(E11:E11) -> 1418442.3
A13: 300 | B13: Control Room
A14: 300.1 | B14: Rasilient AS61MTv2-2xGbE-1xi7-12700 16GB-T400-1x500GB NO_HDD-Win10-KBM - ApplianceStor61v2 for CCTV Viewing Mini-Tower, Intel i7-12700 CPU, 16GB DDR4-3200 non-ECC RAM, Nvidia T400 GPU, 2xGbE, 1x500GB SDD, Win10 Pro, USB Keyboard and Mouse | C14: ='Workbook VSS'!E11*163 -> 410481.27 | D14: ='Workbook VSS'!B11 -> 1 | E14: =C14*D14 -> 410481.27 | F14: 410481.27
A15: 300.2 | B15: GVision 43in CCTV Monitor, Desktop, VGA + HDMI + BNC In/Out(CVBS), HD 1920x1080, 250 Nits, 1000:1 Contrast, 100 x 200mm VESA, 2 x 5W, Black, Stand | C15: ='Workbook VSS'!E12*163 -> 550125 | D15: ='Workbook VSS'!B20 -> 1 | E15: =C15*D15 -> 550125 | F15: 550125
C16: Sub-Total | E16: =SUM(E14:E15) -> 960606.27
A17: 400 | B17: Video Security Equipment
A18: 400.1 | B18: AXIS P3268-LVE High-performance fixed dome camera with Deep Learning Processing Unit (DLPU). Forensic WDR, Lightfinder 2.0 and Optimized IR. Discreet, dust- and IK10 vandal-resistant outdoor casing. Varifocal 3-8 mm P-Iris lens with remote zoom and focus. Multiple, individually configurable streams, H.264/H.265 with Zipstream and Motion JPEG. 8MP 4K stream in 16:9 up to 30fps. | C18: ='Workbook VSS'!E17*163 -> 174658.58 | D18: ='Workbook VSS'!B17 -> 3 | E18: =C18*D18 -> 523975.73 | F18: 174658.58
A19: 400.2 | B19: AXIS P3267-LV High-performance fixed dome camera with Deep Learning Processing Unit (DLPU). Forensic WDR, Lightfinder 2.0 and Optimized IR. Discreet, dust- and IK10 vandal-resistant indoor casing. Varifocal 3-8 mm P-Iris lens with remote zoom and focus. Multiple, individually configurable streams, H.264/H.265 with Zipstream and Motion JPEG. | C19: ='Workbook VSS'!E18*163 -> 134927.32 | D19: ='Workbook VSS'!B18 -> 7 | E19: =C19*D19 -> 944491.27 | F19: 134927.33
A20: 400.3 | B20: AXIS P3267-LVE High-performance fixed dome camera with Deep Learning Processing Unit (DLPU). Forensic WDR, Lightfinder 2.0 and Optimized IR. Discreet, dust- and IK10 vandal-resistant outdoor casing. Varifocal 3-8 mm P-Iris lens with remote zoom and focus. Multiple, individually configurable streams, H.264/H.265 with Zipstream and Motion JPEG. 5MP stream in 4:3 up to 30fps. | C20: ='Workbook VSS'!E19*163 -> 158766.07 | D20: ='Workbook VSS'!B19 -> 2 | E20: =C20*D20 -> 317532.15 | F20: 158766.08
C21: Total Camera | E21: =SUM(E18:E20) -> 1785999.1
A22: 500 | B22: Network
A23: 500.1 | B23: AXIS T8516 PoE+ Network Switch managed gigabit network switch, optimized for Axis network products. 2 SFP/RJ45 uplink ports and 16 PoE+ ports with 250W power supply. Built in DCHP server for plug-and-play camera setup. Easy system configuration for effective installation of Axis network products. | C23: ='Workbook VSS'!E25*163 -> 125391.82 | D23: ='Workbook VSS'!B25 -> 1 | E23: =C23*D23 -> 125391.82 | F23: 125391.82
A24: 500.2 | B24: AXIS T8508 PoE+ Network Switch managed fanless gigabit network switch, optimized for Axis network products. 2 SFP/RJ45 uplink ports and 8 PoE+ ports with 130W power supply. Built in DCHP server for plug-and-play camera setup. Easy system configuration for effective installation of Axis network products | C24: ='Workbook VSS'!E26*163 -> 76125.075 | D24: ='Workbook VSS'!B26 -> 3 | E24: =C24*D24 -> 228375.22 | F24: 76125.075
C25: Network Total | E25: =SUM(E23:E24) -> 353767.05
A26: 600 | B26: Network Infrastructure
A27: 600.1 | B27: trueCABLE Cat6 Riser (CMR), 1000ft, Green, 23AWG 4 Pair Solid Bare Copper, 550MHz, PoE++ (4PPoE), ETL Listed, Unshielded Twisted Pair (UTP), Bulk Ethernet Cable | C27: ='Workbook VSS'!E32*163 -> 42380 | D27: ='Workbook VSS'!B32 -> 6 | E27: =C27*D27 -> 254280 | F27: 42380
A28: 600.2 | B28: Miscellaneous Material | C28: ='Workbook VSS'!E33*163 -> 148330 | D28: ='Workbook VSS'!B33 -> 1 | E28: =C28*D28 -> 148330
A29: 600.3 | B29: Infrastructure Installation | C29: ='Workbook VSS'!E34*163 -> 105950 | D29: ='Workbook VSS'!B34 -> 1 | E29: =C29*D29 -> 105950
A30: 600.4 | B30: Labor to Install Data Cables, Test & Label | C30: ='Workbook VSS'!E35*163 -> 9535.5 | D30: ='Workbook VSS'!B35 -> 13 | E30: =C30*D30 -> 123961.5
C31: Infra Total | E31: =SUM(E27:E30) -> 632521.5
A32: 700 | B32: Professional Services
A33: 700.1 | B33: Equipment installation. All wiring must be certified before equipment is installed. This includes connections from cable to equipment. | C33: ='Workbook VSS'!E39*163 -> 24450 | D33: ='Workbook VSS'!B39 -> 18 | E33: =C33*D33 -> 440100
A34: 700.3 | B34: Equipment adjustment, software and platform installation, programming, internal configuration of system and system testing. | C34: ='Workbook VSS'!E40*163 -> 6112.5 | D34: ='Workbook VSS'!B40 -> 12 | E34: =C34*D34 -> 73350
A35: 700.4 | B35: Professional Serves - Project Management | C35: ='Workbook VSS'!E41*163 -> 412778.58 | D35: ='Workbook VSS'!B41 -> 1 | E35: =C35*D35 -> 412778.58
C36: Sub-Total | E36: =SUM(E33:E35) -> 926228.58
A37: 700.5 | B37: Contingency plan | C37: ='Workbook VSS'!E42*163 -> 591649.3 | D37: ='Workbook VSS'!B42 -> 0 | E37: =C37*D37 -> 0
C38: Sub-Total | E38: =E37 -> 0
A39: 800 | B39: Importation
A40: 800.1 | B40: Shipping / Freight (CIF Jamaica) | C40: =('Workbook VSS'!G27+'Workbook VSS'!G21+'Workbook VSS'!G12)*163 -> 910355 | D40: 1 | E40: =C40*D40 -> 910355
...

Sheet EAC
A1: Company Name | B1: MoH ARC Building
A2: Address
A3: City/Twon | H3: State/Parish | P3: Code
A4: Phone | F4: Email | P4: Web
A5: Company Detail:
A7: Notes
A9: Contact | J9: Title
A10: Office Phone | J10: Mobile
A11: Email
A12: Project | J12: Site
A13: Access Control Site Assessment
A14: Area | B14: Door | D14: Read Access | I14: Lock Type | L14: Controller | P14: Accessories | U14: Building Grouping | V14: Comment
D15: Bio | E15: LR | F15: In | G15: Out | H15: RTE | I15: 600 | J15: 1200 | K15: Z | L15: 2 | M15: 4 | N15: 8 | O15: 16 | P15: Panel | Q15: Contact | R15: Imput | S15: Tx | T15: OR
A16: Ground Floor
A17: Main Entrance | F17: 1 | G17: 1 | I17: 1 | M17: 1 | Q17: 1 | V17: slimline
A18: Office 1 | F18: 1 | G18: 1 | I18: 1 | K18: 1 | Q18: 1 | V18: slimline
A19: Front Entrance | R19: 1 | V19: Garage Contact
A20: Main Entrance - Intercom | V20: Intercome
A21: 1st Floor
A22: Nursing and midwife unit Entrance | F22: 1 | G22: 1 | I22: 1 | L22: 1 | Q22: 1 | V22: slimline
A24: 2nd Floor
A25: Epidemiology - Entrance | F25: 1 | G25: 1 | I25: 1 | L25: 1 | Q25: 1 | V25: slimline
A27: 3rd Floor
A28: Epidemiology - Entrance | F28: 1 | G28: 1 | I28: 1 | L28: 1 | Q28: 1 | V28: slimline
A30: 4th Floor
A31: Accounts - Entrance | F31: 1 | G31: 1 | I31: 1 | L31: 1 | Q31: 1 | V31: slimline
A33: 5th Floor
A34: Environmental health | F34: 1 | G34: 1 | I34: 1 | L34: 1 | Q34: 1
A35: Directors Office | F35: 1 | H35: 1 | I35: 1 | L35: 1 | V35: Door needs closure - slimline reader
A38: 6th Floor
A40: Entrance to Roof | F40: 1 | H40: 1 | I40: 1 | L40: 1 | Q40: 1 | V40: slimline
A52: Total | D52: =SUM(D48:D49) -> 0 | E52: =SUM(E48:E49) -> 0 | F52: =SUM(F17:F50) -> 9 | G52: =SUM(G17:G50) -> 7 | H52: =SUM(H17:H49) -> 2 | I52: =SUM(I17:I49) -> 9 | K52: =SUM(K17:K49) -> 1 | L52: =SUM(L17:L49) -> 7 | M52: =SUM(M17:M49) -> 1 | N52: =SUM(N48:N49) -> 0 | O52: =SUM(O48:O49) -> 0 | P52: =SUM(P48:P49) -> 0 | Q52: =SUM(Q17:Q49) -> 8 | R52: =SUM(R48:R49) -> 0 | S52: =SUM(S48:S49) -> 0 | T52: =SUM(T48:T49) -> 0
B54: Total | D54: =D52+D47+D43+D38+D33 -> 0 | E54: =E52+E47+E43+E38+E33 -> 0 | F54: =F52+F47+F43+F38+F33 -> 9 | G54: =G52+G47+G43+G38+G33 -> 7 | H54: =H52+H47+H43+H38+H33 -> 2 | I54: =I52+I47+I43+I38+I33 -> 9 | J54: =J52+J47+J43+J38+J33 -> 0 | K54: =K52+K47+K43+K38+K33 -> 1 | ... T54: =T52+T47+T43+T38+T33 -> 0
F55: =SUM(F54:G54) -> 16

Sheet Workbook EAC
A1: Item | B1: QTY | C1: Cost | D1: Mark up % | E1: Sell | F1: Cost | G1: Total | H1: Profit
A2: Hardware
A3: EN-2DBC-PLUS | B3: =EAC!L54 -> 7 | C3: 650 | D3: =C3*0.35 -> 227.5 | E3: =C3+D3 -> 877.5 | F3: =B3*C3 -> 4550 | G3: =E3*B3 -> 6142.5 | H3: =D3*B3 -> 1592.5 | I3: =C3*163 -> 105950
A4: E-EAP-5D5Q | B4: 7 | C4: 50 | D4: =C4*0.35 -> 17.5 | E4: =C4+D4 -> 67.5 | F4: =B4*C4 -> 350 | G4: =E4*B4 -> 472.5 | H4: =D4*B4 -> 122.5 | I4: =C4*163 -> 8150
A5: M2150-4DBC | B5: =EAC!M54 -> 1 | C5: 1138.15 | D5: =C5*0.35 -> 398.3525 | E5: =C5+D5 -> 1536.5025 | F5: =B5*C5 -> 1138.15 | G5: =E5*B5 -> 1536.5025 | H5: =D5*B5 -> 398.3525 | I5: =C5*163 -> 185518.45
A6: WIM4 | B6: =B5 -> 1 | C6: 164.45 | D6: =C6*0.35 -> 57.5575 | E6: =C6+D6 -> 222.0075 | F6: =B6*C6 -> 164.45 | G6: =E6*B6 -> 222.0075 | H6: =D6*B6 -> 57.5575 | I6: =C6*163 -> 26805.35
A7: MN-NIC-5 | B7: =B5 -> 1 | C7: 242.45 | D7: =C7*0.35 -> 84.8575 | E7: =C7+D7 -> 327.3075 | F7: =B7*C7 -> 242.45 | G7: =E7*B7 -> 327.3075 | H7: =D7*B7 -> 84.8575 | I7: =C7*163 -> 39519.35
A8: MN-CAB3A | B8: 1 | C8: 221.65 | D8: =C8*0.35 -> 77.5775 | E8: =C8+D8 -> 299.2275 | F8: =B8*C8 -> 221.65 | G8: =E8*B8 -> 299.2275 | H8: =D8*B8 -> 77.5775 | I8: =C8*163 -> 36128.95
A9: MN-CAB-FIX | B9: =B8 -> 1 | C9: 40.95 | D9: =C9*0.35 -> 14.3325 | E9: =C9+D9 -> 55.2825 | F9: =B9*C9 -> 40.95 | G9: =E9*B9 -> 55.2825 | H9: =D9*B9 -> 14.3325 | I9: =C9*163 -> 6674.85
A10: MN-PSU-KIT | B10: =B8 -> 1 | C10: 128.7 | D10: =C10*0.35 -> 45.045 | E10: =C10+D10 -> 173.745 | F10: =B10*C10 -> 128.7 | G10: =E10*B10 -> 173.745 | H10: =D10*B10 -> 45.045 | I10: =C10*163 -> 20978.1
A11: MN-TRANS-75-UL | B11: =B8 -> 1 | C11: 162.5 | D11: =C11*0.35 -> 56.875 | E11: =C11+D11 -> 219.375 | F11: =B11*C11 -> 162.5 | G11: =E11*B11 -> 219.375 | H11: =D11*B11 -> 56.875 | I11: =C11*163 -> 26487.5
A12: M2150-AC8/4 | B12: 1 | C12: 196.95 | D12: =C12*0.35 -> 68.9325 | E12: =C12+D12 -> 265.8825 | F12: =B12*C12 -> 196.95 | G12: =E12*B12 -> 265.8825 | H12: =D12*B12 -> 68.9325 | I12: =C12*163 -> 32102.85
A13: 939S | B13: =EAC!F55 -> 16 | C13: 333.45 | D13: =C13*0.35 -> 116.7075 | E13: =C13+D13 -> 450.1575 | F13: =B13*C13 -> 5335.2 | G13: =E13*B13 -> 7202.52 | H13: =D13*B13 -> 1867.32 | I13: =C13*163 -> 54352.35
A14: SD-7103GC-PEQ | B14: =EAC!H54 -> 2 | C14: 39 | D14: =C14*0.35 -> 13.65 | E14: =C14+D14 -> 52.65 | F14: =B14*C14 -> 78 | G14: =E14*B14 -> 105.3 | H14: =D14*B14 -> 27.3 | I14: =C14*163 -> 6357
A15: E-941SA-600PQ | B15: =EAC!I54 -> 9 | C15: 85 | D15: =C15*0.35 -> 29.75 | E15: =C15+D15 -> 114.75 | F15: =B15*C15 -> 765 | G15: =E15*B15 -> 1032.75 | H15: =D15*B15 -> 267.75 | I15: =C15*163 -> 13855
A16: E-941S-600/ZQ | B16: =EAC!K54 -> 1 | C16: 53 | D16: =C16*0.35 -> 18.55 | E16: =C16+D16 -> 71.55 | F16: =B16*C16 -> 53 | G16: =E16*B16 -> 71.55 | H16: =D16*B16 -> 18.55 | I16: =C16*163 -> 8639
A17: Shipping | B17: 1 | C17: 1200 | D17: =C17*0.35 -> 420 | E17: =C17+D17 -> 1620 | F17: =B17*C17 -> 1200 | G17: =E17*B17 -> 1620 | H17: =D17*B17 -> 420 | I17: =C17*163 -> 195600
E18: Total | F18: =SUM(F3:F17) -> 14627 | G18: =SUM(G3:G17) -> 19746.45 | H18: =SUM(H3:H17) -> 5119.45
E19: Import Tax | F19: =F18*0.44 -> 6435.88 | G19: =G18*0.44 -> 8688.438
A21: Computers | S21: 650 | T21: =S21*1.35 -> 877.5
A22: Item | B22: QTY | C22: Cost | D22: Mark up % | E22: Sell | F22: Cost | G22: Total | H22: Profit | I22: =C17+C52 -> 3200 | J22: =I22*163 -> 521600
D23: =C23*25% -> 0 | E23: =D23+C23 -> 0 | F23: =C23*B23 -> 0 | G23: =E23*B23 -> 0 | H23: =D23*B23 -> 0 | J23: 52.08 | K23: =J23*1.35 -> 70.308
D24: =C24*25% -> 0 | E24: =D24+C24 -> 0 | F24: =C24*B24 -> 0 | G24: =E24*B24 -> 0 | H24: =D24*B24 -> 0
E25: Total | F25: =F24+F23 -> 0 | G25: =G24+G23 -> 0 | H25: =H24+H23 -> 0
E26: Import Tax | F26: =F25*22% -> 0 | G26: =G25*22% -> 0
A28: Software
A29: Item | B29: QTY | C29: Cost | D29: Mark up % | E29: Sell | F29: Cost | G29: Total | H29: Profit
A30: PRO-LIC-016-V9 | B30: 1 | C30: 482.62 | D30: =C30*0.35 -> 168.917 | E30: =C30+D30 -> 651.537 | F30: =C30*B30 -> 482.62 | G30: =E30*B30 -> 651.537 | H30: =D30*B30 -> 168.917 | I30: =C30*163 -> 78667.06
A31: PRO-CLIENT-V9.5 | B31: 1 | C31: 572 | D31: =C31*0.35 -> 200.2 | E31: =C31+D31 -> 772.2 | F31: =C31*B31 -> 572 | G31: =E31*B31 -> 772.2 | H31: =D31*B31 -> 200.2 | I31: =C31*163 -> 93236
A32: SSA-ADD-YEARS | C32: 1076 | D32: =C32*0.35 -> 376.6 | E32: =C32+D32 -> 1452.6 | F32: =C32*B32 -> 0 | G32: =E32*B32 -> 0 | H32: =D32*B32 -> 0 | I32: =C32*163 -> 175388
E33: Total | F33: =SUM(F30:F32) -> 1054.62 | G33: =SUM(G30:G32) -> 1423.737 | H33: =SUM(H30:H32) -> 369.117
A35: Credential Centre
A36: Item | B36: QTY | C36: Cost | D36: Mark up % | E36: Sell | F36: Cost | G36: Total | H36: Profit
D37: =C37*0.3 -> 0 | E37: =D37+C37 -> 0 | F37: =C37*B37 -> 0 | G37: =E37*B37 -> 0 | H37: =D37*B37 -> 0
D38: =C38*0.3 -> 0 | E38: =D38+C38 -> 0 | F38: =C38*B38 -> 0 | G38: =E38*B38 -> 0 | H38: =D38*B38 -> 0
D39: =C39*0.3 -> 0 | E39: =D39+C39 -> 0 | F39: =C39*B39 -> 0 | G39: =E39*B39 -> 0 | H39: =D39*B39 -> 0
D40: =C40*0.3 -> 0 | E40: =D40+C40 -> 0 | F40: =C40*B40 -> 0 | G40: =E40*B40 -> 0 | H40: =D40*B40 -> 0
D41: =C41*0.3 -> 0 | E41: =D41+C41 -> 0 | F41: =C41*B41 -> 0 | G41: =E41*B41 -> 0 | H41: =D41*B41 -> 0
D42: =C42*0.3 -> 0 | E42: =D42+C42 -> 0 | F42: =C42*B42 -> 0 | G42: =E42*B42 -> 0 | H42: =D42*B42 -> 0
E43: Total | F43: =SUM(F39:F42) -> 0 | G43: =SUM(G39:G42) -> 0 | H43: =SUM(H39:H42) -> 0
...

Sheet EAC BoM
A1: Ministry of Health & Wellness
A2: Ref # SurAc-1-6-2026 - Access Control
A3: Item No | B3: Products – Description | C3: List | D3: Qty | E3: Extended
A4: 900 | B4: Access Control System Software
A5: 900.1 | B5: AMAG Symmetry Professional 16 Reader License Add-on | C5: ='Workbook EAC'!E30*163 -> 106200.53 | D5: ='Workbook EAC'!B30 -> 1 | E5: =C5*D5 -> 106200.53 | G5: 106200.53
A6: 900.2 | B6: Symmetry Professional Client Software - Includes License. | C6: ='Workbook EAC'!E31*163 -> 125868.6 | D6: ='Workbook EAC'!B31 -> 1 | E6: =C6*D6 -> 125868.6 | G6: 125868.6
C7: Software Total | E7: =SUM(E5:E6) -> 232069.13
A8: 1000 | B8: Hardware
A9: 1000.1 | B9: Symmetry Edge Network 2 Door PoE+ Controller - Power over Ethernet+ capable one door controller with 2 aux inputs and 1 aux outputs. Upgradable to 2 doors with reader module. Provides 1.5A power for reader using PoE+ (750mA using PoE), lock & devices. | C9: ='Workbook EAC'!E3*163 -> 143032.5 | D9: ='Workbook EAC'!B3 -> 7 | E9: =C9*D9 -> 1001227.5 | G9: 143032.5
A10: 1000.4 | B10: Power Supply with Enclouser (12VDC) to Power Access Control Lock | C10: ='Workbook EAC'!E4*163 -> 11002.5 | D10: ='Workbook EAC'!B4 -> 7 | E10: =C10*D10 -> 77017.5 | G10: 11002.5
A11: 1000.5 | B11: Symmetry M2150 4DBC 4 Reader Panel BOARD ONLY - 20K | C11: ='Workbook EAC'!E5*163 -> 250449.91 | D11: ='Workbook EAC'!B5 -> 1 | E11: =C11*D11 -> 250449.91 | G11: 250449.91
A12: 1000.7 | B12: Symmetry Wiegand Interface Module (WIM) 4 - Used with 4 door controllers to enable Wiegand reader connection | C12: ='Workbook EAC'!E6*163 -> 36187.222 | D12: ='Workbook EAC'!B6 -> 1 | E12: =C12*D12 -> 36187.222 | G12: 36187.223
A13: 1000.8 | B13: Symmetry M2150 - 10/100Mbps NIC module for Ethernet connection of panel to LAN | C13: ='Workbook EAC'!E7*163 -> 53351.122 | D13: ='Workbook EAC'!B7 -> 1 | E13: =C13*D13 -> 53351.122 | G13: 53351.122
A14: 1000.9 | B14: Symmetry CAB3A Enclosure - Lock, Tamper, Space for PSU-KIT. Supports: DBU & QTY 1x AC24/4, OC4/24, 4DC, 2DC or QTY 2x 2DC, 4DC, AC24/4, OC4/24 or QTY: 1x 8DBC, 8DC, 4DBC, 2DBC (WHD 16.5x21.7x3.7)* | C14: ='Workbook EAC'!E8*163 -> 48774.083 | D14: ='Workbook EAC'!B8 -> 1 | E14: =C14*D14 -> 48774.083 | G14: 48774.082
A15: 1000.1 | B15: Symmetry M2150 Board Fixing Kit - For adding Boards to existing enclosure. Includes standoffs, screws, etc. | C15: ='Workbook EAC'!E9*163 -> 9011.0475 | D15: ='Workbook EAC'!B9 -> 1 | E15: =C15*D15 -> 9011.0475 | G15: 9011.0475
A16: 1000.11 | B16: Symmetry 3 Amp Power Supply - Provides AC power. Requires 18VAC UL Transformer | C16: ='Workbook EAC'!E10*163 -> 28320.435 | D16: ='Workbook EAC'!B10 -> 1 | E16: =C16*D16 -> 28320.435 | G16: 28320.435
A17: 1000.13 | B17: Symmetry 75VA UL Transformer - 110v/18VAC, 75VA. For use with M2150 2DBC, 2DC. 4DBC or 4DC controllers. UL294 | C17: ='Workbook EAC'!E11*163 -> 35758.125 | D17: ='Workbook EAC'!B11 -> 1 | E17: =C17*D17 -> 35758.125 | G17: 35758.125
A18: 1000.15 | B18: Symmetry M2150 8 Input/4 Output Module - (NOTE: Max combined AC8/4 and OC4/8 modules for M2150 family: 8DC, 8DBC: Max 1; 4DC, 4DBC: max 2; 2DC, 2DBC: max 1; Not applicable for EN-1DBC, EN-2DBC, or any DBU) | C18: ='Workbook EAC'!E12*163 -> 43338.847 | D18: ='Workbook EAC'!B12 -> 1 | E18: =C18*D18 -> 43338.847 | G18: 43338.848
A19: 1000.16 | B19: Symmetry Blue 939S (Wiegand + OSDP) Wallplate Reader - Black - for Bluetooth / LF + HF | C19: ='Workbook EAC'!E13*163 -> 73375.673 | D19: ='Workbook EAC'!B13 -> 16 | E19: =C19*D19 -> 1174010.8 | G19: 73375.673
A20: 1000.17 | B20: Seco-Larm Enforcer Slimline Push-to-Exit Plate, Illuminated | C20: ='Workbook EAC'!E14*163 -> 8581.95 | D20: ='Workbook EAC'!B14 -> 2 | E20: =C20*D20 -> 17163.9 | G20: 8581.95
... A22: 1000.19 | B22: Seco-Larm"Z" Mounting Bracket for 600lb. Series - Armature Plate Not Included | C22: ='Workbook EAC'!E16*163 -> 11662.65 | D22: ='Workbook EAC'!B16 -> 1 | E22: =C22*D22 -> 11662.65 | G22: 11662.65
C23: Hardware Total | E23: =SUM(E9:E22) -> 2954611.3
A24: 1100 | B24: Infrastructure
A25: 1100.1 | B25: Cat6 24AWG Stranded - CM, 1000ft, Unshielded, More Flexible, Bare Copper, 550MHz, ETL Listed & UL Listed | C25: ='Workbook EAC'!E48*163 -> 35208 | D25: ='Workbook EAC'!B48 -> 4 | E25: =C25*D25 -> 140832 | G25: 35208
A26: 1100.2 | B26: Infrastructure Installation | C26: ='Workbook EAC'!E49*163 -> 55012.5 | D26: ='Workbook EAC'!B49 -> 1 | E26: =C26*D26 -> 55012.5 | G26: 55012.5
A27: 1100.3 | B27: Labor to Install Data Cables, Test & Label | C27: ='Workbook EAC'!E50*163 -> 8802 | D27: ='Workbook EAC'!B50 -> 21 | E27: =C27*D27 -> 184842 | G27: 8802
A28: 1100.4 | B28: Miscellaneous Material | C28: ='Workbook EAC'!E51*163 -> 55012.5 | D28: ='Workbook EAC'!B51 -> 1 | E28: =C28*D28 -> 55012.5 | G28: 55012.5
C29: Infra Total | E29: =SUM(E25:E28) -> 435699
A30: 1200 | B30: Professional Services
A31: 1200.1 | B31: Equipment installation. All wiring must be certified before equipment is installed. This includes connections from cable to equipment. | C31: ='Workbook EAC'!E57*163 -> 24450 | D31: ='Workbook EAC'!B57 -> 9 | E31: =C31*D31 -> 220050
A32: 1200.2 | B32: Software Platform Installation and Configuration | C32: ='Workbook EAC'!E58*163 -> 6112.5 | D32: ='Workbook EAC'!B58 -> 16 | E32: =C32*D32 -> 97800
A33: 1200.3 | B33: Professional Serves - Project Management | C33: ='Workbook EAC'!E59*163 -> 425200.47 | D33: ='Workbook EAC'!B59 -> 1 | E33: =C33*D33 -> 425200.47
C34: PS Total | E34: =SUM(E31:E33) -> 743050.47
A35: 1200.5 | B35: Contingency plan | C35: ='Workbook EAC'!E60*163 -> 609454.01 | D35: ='Workbook EAC'!B60 -> 0 | E35: =C35*D35 -> 0
C36: PS Total | E36: =E35 -> 0
A37: 1300 | B37: Importation | G37: 1174415
A38: 1300.1 | B38: Shipping / Freight (CIF Jamaica) | C38: ='Workbook EAC'!E17*163 -> 264060 | D38: 1 | E38: =C38*D38 -> 264060 | G38: 2346491.9
A39: 1300.2 | B39: Importation Tax (Import Duty, Stamp Duty, IMP-GCT, SCT, SCF, CUF, Processing Fee, Environmental Levy) | C39: ='Workbook EAC'!G65*163 -> 1094949.2 | D39: 1 | E39: =C39*D39 -> 1094949.2
C40: Import Total | E40: =SUM(E38:E39) -> 1359009.2
C42: Sub-Total | E42: =E40+E36+E34+E29+E23+E7 -> 5724439.2
...

Sheet Intercom
A1: Item | B1: QTY | C1: Cost | D1: Mark up % | E1: Sell | F1: Cost | G1: Total | H1: Profit
A2: Software
D3: =C3*25% -> 0 | E3: =C3+D3 -> 0 | F3: =B3*C3 -> 0 | G3: =E3*B3 -> 0 | H3: =D3*B3 -> 0
D4: =C4*25% -> 0 | E4: =C4+D4 -> 0 | F4: =B4*C4 -> 0 | G4: =E4*B4 -> 0 | H4: =D4*B4 -> 0
D5: =C5*25% -> 0 | E5: =C5+D5 -> 0 | F5: =B5*C5 -> 0 | G5: =E5*B5 -> 0 | H5: =D5*B5 -> 0
D6: =C6*25% -> 0 | E6: =C6+D6 -> 0 | F6: =B6*C6 -> 0 | G6: =E6*B6 -> 0 | H6: =D6*B6 -> 0
E7: Total | F7: =SUM(F3:F6) -> 0 | G7: =SUM(G3:G6) -> 0 | H7: =SUM(H3:H6) -> 0
A9: Item | B9: QTY | C9: Cost | D9: Mark up % | E9: Sell | F9: Cost | G9: Total | H9: Profit
A10: Hardware
D11: =C11*25% -> 0 | E11: =C11+D11 -> 0 | F11: =B11*C11 -> 0 | G11: =E11*B11 -> 0 | H11: =D11*B11 -> 0
D12: =C12*25% -> 0 | E12: =C12+D12 -> 0 | F12: =B12*C12 -> 0 | G12: =E12*B12 -> 0 | H12: =D12*B12 -> 0
D13: =C13*25% -> 0 | E13: =C13+D13 -> 0 | F13: =B13*C13 -> 0 | G13: =E13*B13 -> 0 | H13: =D13*B13 -> 0
D14: =C14*25% -> 0 | E14: =C14+D14 -> 0 | F14: =B14*C14 -> 0 | G14: =E14*B14 -> 0 | H14: =D14*B14 -> 0
D15: =C15*25% -> 0 | E15: =C15+D15 -> 0 | F15: =B15*C15 -> 0 | G15: =E15*B15 -> 0 | H15: =D15*B15 -> 0
D16: =C16*25% -> 0 | E16: =C16+D16 -> 0 | F16: =B16*C16 -> 0 | G16: =E16*B16 -> 0 | H16: =D16*B16 -> 0
D17: =C17*25% -> 0 | E17: =C17+D17 -> 0 | F17: =B17*C17 -> 0 | G17: =E17*B17 -> 0 | H17: =D17*B17 -> 0
D18: =C18*25% -> 0 | E18: =C18+D18 -> 0 | F18: =B18*C18 -> 0 | G18: =E18*B18 -> 0 | H18: =D18*B18 -> 0
E19: Total | F19: =SUM(F11:F18) -> 0 | G19: =SUM(G11:G18) -> 0 | H19: =SUM(H11:H18) -> 0
E20: Import Tax | F20: =F19*50% -> 0 | G20: =F20 -> 0
A22: Infrastructure
B23: QTY | C23: Cost | D23: Mark up % | E23: Sell | F23: Cost | G23: Total | H23: Profit
D24: =C24*25% -> 0 | E24: =D24+C24 -> 0 | F24: =C24*B24 -> 0 | G24: =E24*B24 -> 0 | H24: =D24*B24 -> 0
D25: =C25*25% -> 0 | E25: =D25+C25 -> 0 | F25: =C25*B25 -> 0 | G25: =E25*B25 -> 0 | H25: =D25*B25 -> 0
D26: =C26*25% -> 0 | E26: =D26+C26 -> 0 | F26: =C26*B26 -> 0 | G26: =E26*B26 -> 0 | H26: =D26*B26 -> 0
D27: =C27*25% -> 0 | E27: =D27+C27 -> 0 | F27: =C27*B27 -> 0 | G27: =E27*B27 -> 0 | H27: =D27*B27 -> 0
E28: Total | F28: =SUM(F24:F27) -> 0 | G28: =SUM(G24:G27) -> 0 | H28: =SUM(H24:H27) -> 0
A30: Professional Services
D31: =C31*50% -> 0 | E31: =D31+C31 -> 0 | F31: =C31*B31 -> 0 | G31: =E31*B31 -> 0 | H31: =D31*B31 -> 0
D32: =C32*50% -> 0 | E32: =D32+C32 -> 0 | F32: =C32*B32 -> 0 | G32: =E32*B32 -> 0 | H32: =D32*B32 -> 0
D33: =C33*50% -> 0 | E33: =D33+C33 -> 0 | F33: =C33*B33 -> 0 | G33: =E33*B33 -> 0 | H33: =D33*B33 -> 0
E34: =D34+C34 -> 0 | F34: =C34*B34 -> 0 | G34: =E34*B34 -> 0 | H34: =D34*B34 -> 0
E35: Total | F35: =SUM(F31:F34) -> 0 | G35: =SUM(G31:G34) -> 0 | H35: =SUM(H31:H34) -> 0
F37: Cost | G37: Total | H37: Profit
E38: System | F38: =F35+F28+F19+F7 -> 0 | G38: =G35+G28+G19+G7 -> 0 | H38: =H35+H28+H19+H7 -> 0
E39: Total Imp | F39: =F20 -> 0 | G39: =G20 -> 0 | H39: =H20 -> 0
E40: Subtotal | F40: =SUM(F38:F39) -> 0 | G40: =SUM(G38:G39) -> 0 | H40: =SUM(H38:H39) -> 0
E41: GCT | F41: =F40*15% -> 0 | G41: =G40*15% -> 0
E42: Grand Total | F42: =F41+F40 -> 0 | G42: =G41+G40 -> 0 | H42: =H41+H40 -> 0

Sheet Intercom BoM
A2: Audio & Video Intercom Rev.1
A3: Item | B3: Products – Description | C3: List | D3: Qty | E3: Extended
B4: Software
C5: =Intercom!E3 -> 0 | D5: =Intercom!B3 -> 0 | E5: =C5*D5 -> 0
C6: =Intercom!E4 -> 0 | D6: =Intercom!B4 -> 0 | E6: =C6*D6 -> 0
C7: =Intercom!E5 -> 0 | D7: =Intercom!B5 -> 0 | E7: =C7*D7 -> 0
C8: =Intercom!E6 -> 0 | D8: =Intercom!B6 -> 0 | E8: =C8*D8 -> 0
C9: Software Total | E9: =SUM(E5:E8) -> 0
B10: Hardware
C11: =Intercom!E11 -> 0 | D11: =Intercom!B11 -> 0 | E11: =C11*D11 -> 0
C12: =Intercom!E12 -> 0 | D12: =Intercom!B12 -> 0 | E12: =C12*D12 -> 0
C13: =Intercom!E13 -> 0 | D13: =Intercom!B13 -> 0 | E13: =C13*D13 -> 0
C14: =Intercom!E14 -> 0 | D14: =Intercom!B14 -> 0 | E14: =C14*D14 -> 0
C15: =Intercom!E15 -> 0 | D15: =Intercom!B15 -> 0 | E15: =C15*D15 -> 0
C16: =Intercom!E16 -> 0 | D16: =Intercom!B16 -> 0 | E16: =C16*D16 -> 0
C17: =Intercom!E17 -> 0 | D17: =Intercom!B17 -> 0 | E17: =C17*D17 -> 0
C18: Hardware Total | E18: =SUM(E11:E17) -> 0
B19: Infrastructure
C20: =Intercom!E24 -> 0 | D20: =Intercom!B24 -> 0 | E20: =C20*D20 -> 0
C21: =Intercom!E25 -> 0 | D21: =Intercom!B25 -> 0 | E21: =C21*D21 -> 0
C22: =Intercom!E26 -> 0 | D22: =Intercom!B26 -> 0 | E22: =C22*D22 -> 0
C23: =Intercom!E27 -> 0 | D23: =Intercom!B27 -> 0 | E23: =C23*D23 -> 0
C24: Inftra Total | E24: =SUM(E20:E23) -> 0
B25: Professional Services
C26: =Intercom!E31 -> 0 | D26: =Intercom!B31 -> 0 | E26: =C26*D26 -> 0
C27: =Intercom!E32 -> 0 | D27: =Intercom!B32 -> 0 | E27: =C27*D27 -> 0
C28: =Intercom!E33 -> 0 | D28: =Intercom!B33 -> 0 | E28: =C28*D28 -> 0
C29: PS Total | E29: =SUM(E26:E28) -> 0
B30: Importation
C31: =Intercom!E18 -> 0 | D31: 1 | E31: =C31*D31 -> 0
C32: =Intercom!F39 -> 0 | D32: 1 | E32: =C32*D32 -> 0
C33: IMP Total | E33: =SUM(E31:E32) -> 0
C35: Sub-Total | E35: =E33+E29+E24+E18+E9 -> 0
C36: GCT | E36: =E35*15% -> 0
C37: Grans-Total | E37: =SUM(E35:E36) -> 0
